c:\MyStuff\CodingProjects\enigmaCOA\trainModelLogisticRegression.py:72: SettingWithCopyWarning:
A value is trying to be set on a copy of a slice from a DataFrame
See the caveats in the documentation: https://pandas.pydata.org/pandas-docs/stable/user_guide/indexing.html#returning-a-view-versus-a-copy
  self.y.loc[self.y.index[i]] = 0
epoch: 1, loss = 0.7318
epoch: 2, loss = 0.7126
epoch: 3, loss = 0.8451
epoch: 4, loss = 0.7681
epoch: 5, loss = 0.9030
epoch: 6, loss = 0.8021
epoch: 7, loss = 1.1017
epoch: 8, loss = 0.7341
epoch: 9, loss = 0.7574
epoch: 10, loss = 0.8146
accuracy = 0.6126
Traceback (most recent call last):
  File "c:\MyStuff\CodingProjects\enigmaCOA\trainModelLogisticRegression.py", line 133, in <module>
  File "C:\Users\lewis\AppData\Local\Programs\Python\Python39\lib\site-packages\wandb\sdk\wandb_run.py", line 394, in wrapper
    return func(self, *args, **kwargs)
  File "C:\Users\lewis\AppData\Local\Programs\Python\Python39\lib\site-packages\wandb\sdk\wandb_run.py", line 345, in wrapper_fn
    return func(self, *args, **kwargs)
  File "C:\Users\lewis\AppData\Local\Programs\Python\Python39\lib\site-packages\wandb\sdk\wandb_run.py", line 335, in wrapper
    return func(self, *args, **kwargs)
  File "C:\Users\lewis\AppData\Local\Programs\Python\Python39\lib\site-packages\wandb\sdk\wandb_run.py", line 1751, in log
    self._log(data=data, step=step, commit=commit)
  File "C:\Users\lewis\AppData\Local\Programs\Python\Python39\lib\site-packages\wandb\sdk\wandb_run.py", line 1527, in _log
    raise ValueError("wandb.log must be passed a dictionary")
ValueError: wandb.log must be passed a dictionary